Workbook

Sheet Kri-Kri Milk Stock Price Histor
A1: Date | B1: Price KRI KRI | C1: Change % | D1: Price ATG | E1: Change %
A2: 43835 | B2: 5.38 | C2: -0.0254 | D2: 923.63 | E2: 0.0038
A3: 43842 | B3: 5.5 | C3: 0.0223 | D3: 934.22 | E3: 0.0115
A4: 43849 | B4: 5.66 | C4: 0.0291 | D4: 948.64 | E4: 0.0154
A5: 43856 | B5: 5.42 | C5: -0.0424 | D5: 910.9 | E5: -0.0398
A6: 43863 | B6: 5.46 | C6: 0.0074 | D6: 910.91 | E6: 0
A7: 43870 | B7: 5.58 | C7: 0.022 | D7: 922.3 | E7: 0.0125
A8: 43877 | B8: 5.42 | C8: -0.0287 | D8: 893.03 | E8: -0.0317
A9: 43884 | B9: 4.64 | C9: -0.1439 | D9: 720.35 | E9: -0.1934
A10: 43891 | B10: 4.48 | C10: -0.0345 | D10: 684.74 | E10: -0.0494
A11: 43898 | B11: 3.85 | C11: -0.1406 | D11: 551.97 | E11: -0.1939
A12: 43905 | B12: 4.55 | C12: 0.1818 | D12: 555.13 | E12: 0.0057
A13: 43912 | B13: 4.35 | C13: -0.044 | D13: 550.85 | E13: -0.0077
... A24: 43989 | B24: 5.48 | C24: -0.0867 | D24: 646.8 | E24: -0.0536
A25: 43996 | B25: 5.4 | C25: -0.0146 | D25: 668.34 | E25: 0.0333 | H25: Απόδοση 5ετίας
A26: 44003 | B26: 5.72 | C26: 0.0593 | D26: 641.95 | E26: -0.0395 | H26: =(B365-B2)/B2 -> 2.7174721 | I26: =(D365-D2)/D2 -> 1.3030867
A27: 44010 | B27: 5.82 | C27: 0.0175 | D27: 658.55 | E27: 0.0259
A28: 44017 | B28: 5.9 | C28: 0.0137 | D28: 632.97 | E28: -0.0388
A29: 44024 | B29: 5.94 | C29: 0.0068 | D29: 641.48 | E29: 0.0134
A30: 44031 | B30: 5.82 | C30: -0.0202 | D30: 634.32 | E30: -0.0112
A31: 44038 | B31: 5.74 | C31: -0.0137 | D31: 617.61 | E31: -0.0263
A32: 44045 | B32: 6.24 | C32: 0.0871 | D32: 632.63 | E32: 0.0243
A33: 44052 | B33: 5.9 | C33: -0.0545 | D33: 634.37 | E33: 0.0028
A34: 44059 | B34: 5.9 | C34: 0 | D34: 633.27 | E34: -0.0017
A35: 44066 | B35: 5.94 | C35: 0.0068 | D35: 634.47 | E35: 0.0019
A36: 44073 | B36: 5.98 | C36: 0.0067 | D36: 639.29 | E36: 0.0076
A37: 44080 | B37: 5.8 | C37: -0.0301 | D37: 636.03 | E37: -0.0051
A38: 44087 | B38: 6.06 | C38: 0.0448 | D38: 658.54 | E38: 0.0354
... A365: 46012 | B365: 20 | C365: 0.004 | D365: 2127.2 | E365: 0.007

Sheet Beta 5-Year
A1: SUMMARY OUTPUT
A3: Regression Statistics
A4: Multiple R | B4: 0.4502939
A5: R Square | B5: 0.20276459
A6: Adjusted R Square | B6: 0.20056229
A7: Standard Error | B7: 0.032287082
A8: Observations | B8: 364
A10: ANOVA
B11: df | C11: SS | D11: MS | E11: F | F11: Significance F
A12: Regression | B12: 1 | C12: 0.095978001 | D12: 0.095978001 | E12: 92.069146 | F12: 1.4170623e-19
A13: Residual | B13: 362 | C13: 0.37736894 | D13: 0.0010424556
A14: Total | B14: 363 | C14: 0.47334694
B16: Coefficients | C16: Standard Error | D16: t Stat | E16: P-value | F16: Lower 95% | G16: Upper 95% | H16: Lower 95.0% | I16: Upper 95.0%
A17: Intercept | B17: 0.0037837028 | C17: 0.0017013335 | D17: 2.2239631 | E17: 0.02676735 | F17: 0.00043796453 | G17: 0.0071294411 | H17: 0.00043796453 | I17: 0.0071294411
A18: X Variable 1 | B18: 0.53856441 | C18: 0.056128133 | D18: 9.5952669 | E18: 1.4170623e-19 | F18: 0.42818626 | G18: 0.64894256 | H18: 0.42818626 | I18: 0.64894256
A22: RESIDUAL OUTPUT | F22: PROBABILITY OUTPUT
A24: Observation | B24: Predicted Y | C24: Residuals | D24: Standard Residuals | F24: Percentile | G24: Y
A25: 1 | B25: 0.0058302476 | C25: -0.031230248 | D25: -0.96860267 | F25: 0.13736264 | G25: -0.1439
A26: 2 | B26: 0.0099771935 | C26: 0.012322806 | D26: 0.38219048 | F26: 0.41208791 | G26: -0.1406
A27: 3 | B27: 0.012077595 | C27: 0.017022405 | D27: 0.52794801 | F27: 0.68681319 | G27: -0.0883
A28: 4 | B28: -0.017651161 | C28: -0.024748839 | D28: -0.76758251 | F28: 0.96153846 | G28: -0.0867
A29: 5 | B29: 0.0037837028 | C29: 0.0036162972 | D29: 0.11215906 | F29: 1.2362637 | G29: -0.0729
A30: 6 | B30: 0.010515758 | C30: 0.011484242 | D30: 0.3561825 | F30: 1.510989 | G30: -0.0714
A31: 7 | B31: -0.013288789 | C31: -0.015411211 | D31: -0.477977 | F31: 1.7857143 | G31: -0.0699
A32: 8 | B32: -0.10037465 | C32: -0.043525346 | D32: -1.3499338 | F32: 2.0604396 | G32: -0.0684
A33: 9 | B33: -0.022821379 | C33: -0.011678621 | D33: -0.36221114 | F33: 2.3351648 | G33: -0.0684
A34: 10 | B34: -0.10064394 | C34: -0.039956064 | D34: -1.2392329 | F34: 2.6098901 | G34: -0.0683
A35: 11 | B35: 0.00685352 | C35: 0.17494648 | D35: 5.4259457 | F35: 2.8846154 | G35: -0.0667
A36: 12 | B36: -0.00036324314 | C36: -0.043636757 | D36: -1.3533892 | F36: 3.1593407 | G36: -0.0663
... A388: 364 | B388: 0.0075536537 | C388: -0.0035536537 | D388: -0.11021618 | F388: 99.862637 | G388: 0.1818

Sheet Beta 2020
A1: SUMMARY OUTPUT
A3: Regression Statistics
A4: Multiple R | B4: 0.65415478
A5: R Square | B5: 0.42791847
A6: Adjusted R Square | B6: 0.41670119
A7: Standard Error | B7: 0.040143341
A8: Observations | B8: 53
A10: ANOVA
B11: df | C11: SS | D11: MS | E11: F | F11: Significance F
A12: Regression | B12: 1 | C12: 0.061475252 | D12: 0.061475252 | E12: 38.148133 | F12: 1.0843338e-07
A13: Residual | B13: 51 | C13: 0.08218588 | D13: 0.0016114878
A14: Total | B14: 52 | C14: 0.14366113
B16: Coefficients | C16: Standard Error | D16: t Stat | E16: P-value | F16: Lower 95% | G16: Upper 95% | H16: Lower 95.0% | I16: Upper 95.0%
A17: Intercept | B17: 0.0051059339 | C17: 0.0055144476 | D17: 0.92591938 | E17: 0.35884879 | F17: -0.0059647815 | G17: 0.016176649 | H17: -0.0059647815 | I17: 0.016176649
A18: X Variable 1 | B18: 0.62232796 | C18: 0.10075873 | D18: 6.1764175 | E18: 1.0843338e-07 | F18: 0.42004637 | G18: 0.82460954 | H18: 0.42004637 | I18: 0.82460954
A22: RESIDUAL OUTPUT
A24: Observation | B24: Predicted Y | C24: Residuals
A25: 1 | B25: 0.0074707801 | C25: -0.03287078
A26: 2 | B26: 0.012262705 | C26: 0.010037295
A27: 3 | B27: 0.014689784 | C27: 0.014410216
A28: 4 | B28: -0.019662719 | C28: -0.022737281
A29: 5 | B29: 0.0051059339 | C29: 0.0022940661
A30: 6 | B30: 0.012885033 | C30: 0.0091149667
A31: 7 | B31: -0.014621862 | C31: -0.014078138
A32: 8 | B32: -0.11525229 | C32: -0.028647707
A33: 9 | B33: -0.025637067 | C33: -0.0088629328
A34: 10 | B34: -0.11556346 | C34: -0.025036543
A35: 11 | B35: 0.0086532032 | C35: 0.1731468
A36: 12 | B36: 0.00031400859 | C36: -0.044314009
... A77: 53 | B77: 0.013009499 | C77: -0.0038094989

Sheet Beta 2021
A1: SUMMARY OUTPUT
A3: Regression Statistics
A4: Multiple R | B4: 0.37636445
A5: R Square | B5: 0.1416502
A6: Adjusted R Square | B6: 0.1244832
A7: Standard Error | B7: 0.024749824
A8: Observations | B8: 52
A10: ANOVA
B11: df | C11: SS | D11: MS | E11: F | F11: Significance F
A12: Regression | B12: 1 | C12: 0.0050543708 | D12: 0.0050543708 | E12: 8.2513095 | F12: 0.0059606382
A13: Residual | B13: 50 | C13: 0.030627688 | D13: 0.00061255377
A14: Total | B14: 51 | C14: 0.035682059
B16: Coefficients | C16: Standard Error | D16: t Stat | E16: P-value | F16: Lower 95% | G16: Upper 95% | H16: Lower 95.0% | I16: Upper 95.0%
A17: Intercept | B17: 0.0044215074 | C17: 0.0034491782 | D17: 1.2819017 | E17: 0.20578949 | F17: -0.0025063709 | G17: 0.011349386 | H17: -0.0025063709 | I17: 0.011349386
A18: X Variable 1 | B18: 0.45854234 | C18: 0.15963128 | D18: 2.8725093 | E18: 0.0059606382 | F18: 0.13791347 | G18: 0.77917121 | H18: 0.13791347 | I18: 0.77917121
A22: RESIDUAL OUTPUT
A24: Observation | B24: Predicted Y | C24: Residuals
A25: 1 | B25: 0.010244995 | C25: -0.0010449951
A26: 2 | B26: -0.0119026 | C26: 0.0119026
A27: 3 | B27: -0.0020439396 | C27: 0.0050439396
A28: 4 | B28: -0.012957247 | C28: 0.018957247
A29: 5 | B29: 0.013684063 | C29: 0.028315937
A30: 6 | B30: 0.011299642 | C30: 0.011800358
A31: 7 | B31: 0.0075854495 | C31: -0.02168545
A32: 8 | B32: 0.0108411 | C32: 0.0291589
A33: 9 | B33: 0.023313452 | C33: -0.026013452
A34: 10 | B34: 0.018177778 | C34: -0.018177778
A35: 11 | B35: -0.0046117767 | C35: 0.023911777
A36: 12 | B36: 0.01473871 | C36: -0.00663871
... A76: 52 | B76: 0.0057512802 | C76: -0.0057512802

Sheet Beta 2022
A1: SUMMARY OUTPUT
A3: Regression Statistics
A4: Multiple R | B4: 0.42585459
A5: R Square | B5: 0.18135213
A6: Adjusted R Square | B6: 0.16497917
A7: Standard Error | B7: 0.033159448
A8: Observations | B8: 52
A10: ANOVA
B11: df | C11: SS | D11: MS | E11: F | F11: Significance F
A12: Regression | B12: 1 | C12: 0.012178957 | D12: 0.012178957 | E12: 11.076321 | F12: 0.0016463488
A13: Residual | B13: 50 | C13: 0.054977448 | D13: 0.001099549
A14: Total | B14: 51 | C14: 0.067156405
B16: Coefficients | C16: Standard Error | D16: t Stat | E16: P-value | F16: Lower 95% | G16: Upper 95% | H16: Lower 95.0% | I16: Upper 95.0%
A17: Intercept | B17: -0.0060313841 | C17: 0.0046021816 | D17: -1.3105489 | E17: 0.19599842 | F17: -0.015275138 | G17: 0.0032123696 | H17: -0.015275138 | I17: 0.0032123696
A18: X Variable 1 | B18: 0.49286545 | C18: 0.14809166 | D18: 3.3281107 | E18: 0.0016463488 | F18: 0.19541459 | G18: 0.79031631 | H18: 0.19541459 | I18: 0.79031631
A22: RESIDUAL OUTPUT
A24: Observation | B24: Predicted Y | C24: Residuals
A25: 1 | B25: 0.001213738 | C25: -0.010613738
A26: 2 | B26: 0.017281152 | C26: -0.012481152
A27: 3 | B27: -0.0096293019 | C27: -0.018770698
A28: 4 | B28: -0.015445114 | C28: 0.025145114
A29: 5 | B29: 0.0049595154 | C29: 0.0046404846
A30: 6 | B30: 0.0075717023 | C30: -0.029071702
A31: 7 | B31: -0.013720085 | C31: -0.013079915
A32: 8 | B32: -0.020817348 | C32: -0.026782652
A33: 9 | B33: -0.062119472 | C33: 0.048919472
A34: 10 | B34: -0.0022856067 | C34: -0.013714393
A35: 11 | B35: 0.014767538 | C35: -0.0011675379
A36: 12 | B36: -0.017318003 | C36: -0.025481997
... A76: 52 | B76: -0.0014477354 | C76: -0.017552265

Sheet Beta 2023
A1: SUMMARY OUTPUT
A3: Regression Statistics
A4: Multiple R | B4: 0.34024364
A5: R Square | B5: 0.11576574
A6: Adjusted R Square | B6: 0.09842781
A7: Standard Error | B7: 0.031062448
A8: Observations | B8: 53
A10: ANOVA
B11: df | C11: SS | D11: MS | E11: F | F11: Significance F
A12: Regression | B12: 1 | C12: 0.0064424972 | D12: 0.0064424972 | E12: 6.677023 | F12: 0.012673577
A13: Residual | B13: 51 | C13: 0.04920866 | D13: 0.00096487568
A14: Total | B14: 52 | C14: 0.055651157
B16: Coefficients | C16: Standard Error | D16: t Stat | E16: P-value | F16: Lower 95% | G16: Upper 95% | H16: Lower 95.0% | I16: Upper 95.0%
A17: Intercept | B17: 0.0060964519 | C17: 0.0044317891 | D17: 1.3756187 | E17: 0.17495165 | F17: -0.0028007359 | G17: 0.01499364 | H17: -0.0028007359 | I17: 0.01499364
A18: X Variable 1 | B18: 0.45491557 | C18: 0.17605135 | D18: 2.5839936 | E18: 0.012673577 | F18: 0.10147773 | G18: 0.80835341 | H18: 0.10147773 | I18: 0.80835341
A22: RESIDUAL OUTPUT
A24: Observation | B24: Predicted Y | C24: Residuals
A25: 1 | B25: 0.016695985 | C25: 0.028504015
A26: 2 | B26: 0.014193949 | C26: -0.011093949
A27: 3 | B27: 0.011100523 | C27: -0.020300523
A28: 4 | B28: 0.023019311 | C28: -0.072719311
A29: 5 | B29: 0.014148458 | C29: -0.0010484576
A30: 6 | B30: 0.021381615 | C30: -0.037481615
A31: 7 | B31: 0.020835716 | C31: -0.0011357165
A32: 8 | B32: 0.010463641 | C32: 0.0088363586
A33: 9 | B33: 0.0066423506 | C33: -0.00034235063
A34: 10 | B34: -0.017741124 | C34: 0.049041124
A35: 11 | B35: -0.0094161691 | C35: -0.063483831
A36: 12 | B36: 0.0065513675 | C36: 0.042648632
... A77: 53 | B77: 0.012601745 | C77: 0.010398255

Sheet Beta 2024
A1: SUMMARY OUTPUT
A3: Regression Statistics
A4: Multiple R | B4: 0.29235602
A5: R Square | B5: 0.085472043
A6: Adjusted R Square | B6: 0.076593131
A7: Standard Error | B7: 0.030804246
A8: Observations | B8: 105
A10: ANOVA
B11: df | C11: SS | D11: MS | E11: F | F11: Significance F
A12: Regression | B12: 1 | C12: 0.0091345151 | D12: 0.0091345151 | E12: 9.6264093 | F12: 0.0024756085
A13: Residual | B13: 103 | C13: 0.097736863 | D13: 0.00094890159
A14: Total | B14: 104 | C14: 0.10687138
B16: Coefficients | C16: Standard Error | D16: t Stat | E16: P-value | F16: Lower 95% | G16: Upper 95% | H16: Lower 95.0% | I16: Upper 95.0%
A17: Intercept | B17: 0.0072808428 | C17: 0.0030755623 | D17: 2.3673209 | E17: 0.019785167 | F17: 0.0011811904 | G17: 0.013380495 | H17: 0.0011811904 | I17: 0.013380495
A18: X Variable 1 | B18: 0.42723906 | C18: 0.13770154 | D18: 3.1026455 | E18: 0.0024756085 | F18: 0.15414054 | G18: 0.70033759 | H18: 0.15414054 | I18: 0.70033759
A22: RESIDUAL OUTPUT
A24: Observation | B24: Predicted Y | C24: Residuals
A25: 1 | B25: 0.017235513 | C25: 0.027964487
A26: 2 | B26: 0.014885698 | C26: -0.011785698
A27: 3 | B27: 0.011980472 | C27: -0.021180472
A28: 4 | B28: 0.023174136 | C28: -0.072874136
A29: 5 | B29: 0.014842974 | C29: -0.0017429742
A30: 6 | B30: 0.021636075 | C30: -0.037736075
A31: 7 | B31: 0.021123388 | C31: -0.0014233884
A32: 8 | B32: 0.011382338 | C32: 0.0079176622
A33: 9 | B33: 0.0077935297 | C33: -0.0014935297
A34: 10 | B34: -0.015106484 | C34: 0.046406484
A35: 11 | B35: -0.0072880092 | C35: -0.065611991
A36: 12 | B36: 0.0077080818 | C36: 0.041491918
... A129: 105 | B129: 0.015911072 | C129: 0.020788928

Sheet Beta 2025
A1: SUMMARY OUTPUT
A3: Regression Statistics
A4: Multiple R | B4: 0.3285169
A5: R Square | B5: 0.10792336
A6: Adjusted R Square | B6: 0.08971771
A7: Standard Error | B7: 0.033118019
A8: Observations | B8: 51
A10: ANOVA
B11: df | C11: SS | D11: MS | E11: F | F11: Significance F
A12: Regression | B12: 1 | C12: 0.0065018665 | D12: 0.0065018665 | E12: 5.9280158 | F12: 0.018589834
A13: Residual | B13: 49 | C13: 0.053743355 | D13: 0.0010968032
A14: Total | B14: 50 | C14: 0.060245222
B16: Coefficients | C16: Standard Error | D16: t Stat | E16: P-value | F16: Lower 95% | G16: Upper 95% | H16: Lower 95.0% | I16: Upper 95.0%
A17: Intercept | B17: 0.0019789574 | C17: 0.0048625272 | D17: 0.40698125 | E17: 0.68579414 | F17: -0.0077926568 | G17: 0.011750572 | H17: -0.0077926568 | I17: 0.011750572
A18: X Variable 1 | B18: 0.48666087 | C18: 0.19988111 | D18: 2.4347517 | E18: 0.018589834 | F18: 0.084984742 | G18: 0.88833701 | H18: 0.084984742 | I18: 0.88833701
A22: RESIDUAL OUTPUT | F22: PROBABILITY OUTPUT
A24: Observation | B24: Predicted Y | C24: Residuals | D24: Standard Residuals | F24: Percentile | G24: Y
A25: 1 | B25: 0.0075268914 | C25: 0.0085731086 | D25: 0.26149353 | F25: 0.98039216 | G25: -0.0699
A26: 2 | B26: 0.0087435436 | C26: 0.00075645644 | D26: 0.023073131 | F26: 2.9411765 | G26: -0.0663
A27: 3 | B27: 0.0082082166 | C27: -0.023908217 | D27: -0.72923885 | F27: 4.9019608 | G27: -0.0577
A28: 4 | B28: 0.0036336044 | C28: 0.018666396 | D28: 0.56935492 | F28: 6.8627451 | G28: -0.055
A29: 5 | B29: 0.0046555922 | C29: 0.0046444078 | D29: 0.14166187 | F29: 8.8235294 | G29: -0.0516
A30: 6 | B30: 0.016481451 | C30: 0.0082185485 | D30: 0.25067888 | F30: 10.784314 | G30: -0.0447
A31: 7 | B31: 0.0061642409 | C31: -0.012164241 | D31: -0.37102881 | F31: 12.745098 | G31: -0.0301
A32: 8 | B32: -0.0011356722 | C32: 0.0072356722 | D32: 0.22069958 | F32: 14.705882 | G32: -0.0272
A33: 9 | B33: 0.0079162201 | C33: -0.07421622 | D33: -2.2637134 | F33: 16.666667 | G33: -0.0252
A34: 10 | B34: 0.021786055 | C34: 0.013713945 | D34: 0.41829726 | F34: 18.627451 | G34: -0.0161
A35: 11 | B35: 0.0030009452 | C35: -0.0092009452 | D35: -0.28064355 | F35: 20.588235 | G35: -0.016
A36: 12 | B36: 0.013026159 | C36: 0.012073841 | D36: 0.36827145 | F36: 22.54902 | G36: -0.0157
... A75: 51 | B75: 0.0053855835 | C75: -0.0013855835 | D75: -0.042262514 | F75: 99.019608 | G75: 0.0789

Sheet WACC
A1: Υπολογισμός Cost of Equity από capm
A2: Rf | B2: 0.0347 | C2: Greece 10-Year Bond Yield - Investing.com
A3: MRP | B3: ='ATG companies'!D32-WACC!B2 -> 0.11958604 | C3: Average market risk premium Greece 2011-2025| Statista | E3: GR - Market Risk Premia
A4: b | B4: ='Beta 5-Year'!B18 -> 0.53856441
A5: Ke | B5: =B2+B4*B3 -> 0.099104785
A7: Υπολογισμός cost of dept από ισολογισμό
B8: 2020 | C8: 2021 | D8: 2022 | E8: 2023 | F8: 2024
A9: Cost of dept | B9: =-('Ισολογισμοί + KAX'!I14+'Ισολογισμοί + KAX'!J15)/('Ισολογισμοί + KAX'!B28+'Ισολογισμοί + KAX'!B29+'Ισολογισμοί + KAX'!B35+'Ισολογισμοί + KAX'!B36) -> 0.027612173 | C9: =-('Ισολογισμοί + KAX'!J14+'Ισολογισμοί + KAX'!K15)/('Ισολογισμοί + KAX'!C28+'Ισολογισμοί + KAX'!C29+'Ισολογισμοί + KAX'!C35+'Ισολογισμοί + KAX'!C36) -> 0.032632401 | D9: =-('Ισολογισμοί + KAX'!K14+'Ισολογισμοί + KAX'!L15)/('Ισολογισμοί + KAX'!D28+'Ισολογισμοί + KAX'!D29+'Ισολογισμοί + KAX'!D35+'Ισολογισμοί + KAX'!D36) -> 0.019180857 | E9: =-('Ισολογισμοί + KAX'!L14+'Ισολογισμοί + KAX'!M15)/('Ισολογισμοί + KAX'!E28+'Ισολογισμοί + KAX'!E29+'Ισολογισμοί + KAX'!E35+'Ισολογισμοί + KAX'!E36) -> 0.034327093 | F9: =-('Ισολογισμοί + KAX'!M14+'Ισολογισμοί + KAX'!N15)/('Ισολογισμοί + KAX'!F28+'Ισολογισμοί + KAX'!F29+'Ισολογισμοί + KAX'!F35+'Ισολογισμοί + KAX'!F36) -> 0.055661538
A11: Υπολογισμός WACC
B12: 2020 | C12: 2021 | D12: 2022 | E12: 2023 | F12: 2024 | I12: Wacc | J12: =F15*B5+(1-F15)*F9*(1-0.22) -> 0.098589197
A13: Equity | B13: ='Ισολογισμοί + KAX'!I40*'Ισολογισμοί + KAX'!I38 -> 2.1623847e+08 | C13: ='Ισολογισμοί + KAX'!J40*'Ισολογισμοί + KAX'!J38 -> 2.8013425e+08 | D13: ='Ισολογισμοί + KAX'!K40*'Ισολογισμοί + KAX'!K38 -> 204271958 | E13: ='Ισολογισμοί + KAX'!L40*'Ισολογισμοί + KAX'!L38 -> 323322139 | F13: ='Ισολογισμοί + KAX'!M40*'Ισολογισμοί + KAX'!M38 -> 5.1309638e+08
A14: Dept | B14: =SUM('Ισολογισμοί + KAX'!B35:B36,'Ισολογισμοί + KAX'!B28:B29) -> 11361040 | C14: =SUM('Ισολογισμοί + KAX'!C35:C36,'Ισολογισμοί + KAX'!C28:C29) -> 9333147 | D14: =SUM('Ισολογισμοί + KAX'!D35:D36,'Ισολογισμοί + KAX'!D28:D29) -> 15241863 | E14: =SUM('Ισολογισμοί + KAX'!E35:E36,'Ισολογισμοί + KAX'!E28:E29) -> 12522674 | F14: =SUM('Ισολογισμοί + KAX'!F35:F36,'Ισολογισμοί + KAX'!F28:F29) -> 4794837
A15: %Equity | B15: =B13/(B13+B14) -> 0.9500832 | C15: =C13/(C13+C14) -> 0.96775752 | D15: =D13/(D13+D14) -> 0.93056536 | E15: =E13/(E13+E14) -> 0.96271292 | F15: =F13/(F13+F14) -> 0.99074161

Sheet Ισολογισμοί + KAX
A1: Ισολογισμοι (Ποσά σε Ευρώ) | B1: 2020 | C1: 2021 | D1: 2022 | E1: 2023 | F1: 2024 | H1: ΚΑΧ (Ποσά σε Ευρώ) | I1: 2020 | J1: 2021 | K1: 2022 | L1: 2023 | M1: 2024
A2: ΕΝΕΡΓΗΤΙΚΟ | H2: Κύκλος εργασιών | I2: 125982880 | J2: 134599699 | K2: 17188386 | L2: 216329611 | M2: 256401956
A3: Μη κυκλοφορούν ενεργητικό | H3: Κόστος πωληθέντων | I3: -85552940 | J3: -93430745 | K3: -140421046 | L3: -143864302 | M3: -180271900
A4: Ενσώματα πάγια | B4: 64807728 | C4: 71097784 | D4: 73879559 | E4: 82007851 | F4: 102405163 | H4: Μικτό κέρδος | I4: 40429940 | J4: 41168954 | K4: 31462040 | L4: 72465309 | M4: 76130056
A5: Δικαιώματα χρήσης παγίων | B5: 114654 | C5: 631097 | D5: 520111 | E5: 588763 | F5: 464472 | H5: Έξοδα διάθεσης | I5: -18849973 | J5: -21304569 | K5: -24396871 | L5: -28245330 | M5: -34084214
A6: Επενδύσεις σε ακίνητα | B6: 10082 | C6: 10082 | D6: 10082 | E6: 10082 | F6: 10082 | H6: Έξοδα διοίκησης | I6: -3571098 | J6: -3669936 | K6: -3722968 | L6: -4545412 | M6: -5178820
A7: Άυλα περιουσιακά στοιχεία | B7: 386380 | C7: 299894 | D7: 185147 | E7: 193614 | F7: 298206 | H7: Έξοδα έρευνας & ανάπτυξης | I7: -295440 | J7: -300955 | K7: -380279 | L7: -455026 | M7: -500740
A8: Λοιπές μακροπρόθεσμες απαιτήσεις | B8: 46106 | C8: 36173 | D8: 181735 | E8: 169743 | F8: 169795 | H8: Άλλα έσοδα εκμετάλλευσης | I8: 739551 | J8: 648521 | K8: 812691 | L8: 770724 | M8: 934592
A9: Σύνολο μη κυκλοφορούντος ενεργητικού | B9: 65364950 | C9: 72075030 | D9: 74776634 | E9: 82970053 | F9: 103347718 | H9: Λοιπά κέρδη/(ζημίες) καθαρά | I9: 154606 | J9: 123872 | K9: 253020 | L9: 287387 | M9: -51094
A10: Κυκλοφορούντα Στοιχεία του Ενεργητικού | H10: Κέρδη προ φόρων, χρηματοδοτικών και επενδυτικών αποτελεσμάτων | I10: 18607586 | J10: 16665887 | K10: 4027632 | L10: 40277652 | M10: 37249781
A11: Αποθέματα | B11: 14024192 | C11: 11871809 | D11: 15290030 | E11: 17288601 | F11: 24784204 | H11: Αποσβέσεις | I11: 4125198 | J11: 4702107 | K11: 5238273 | L11: 5230234 | M11: 5730182
A12: Πελάτες και λοιπές απαιτήσεις | B12: 24249201 | C12: 23047706 | D12: 28690740 | E12: 26917831 | F12: 32760609 | H12: EBIDTA | I12: =I10+I11 -> 22732784 | J12: =J10+J11 -> 21367994 | K12: =K10+K11 -> 9265905 | L12: =L10+L11 -> 45507886 | M12: =M10+M11 -> 42979963
A13: Απαιτήσεις από φόρο εισοδήματος | B13: 1430104 | C13: 0 | D13: 2110152 | E13: 0 | H13: Χρηματοοικονομικά έσοδα | I13: 125150 | J13: 171652 | K13: 94898 | L13: 453541 | M13: 611764
A14: Χρηματοοικονομικά μέσα | B14: 301852 | C14: 0 | D14: 0 | E14: 3984840 | F14: 0 | H14: Χρηματοοικονομικά έξοδα | I14: -283974 | J14: -278205 | K14: -263526 | L14: -401343 | M14: -266888
A15: Δεσμευμένες καταθέσεις | C15: 2230000 | D15: 0 | E15: 7600000 | F15: 150000 | H15: Χρηματοοικονομικά έξοδα μισθώσεων | I15: -26752 | J15: -29729 | K15: -26358 | L15: -28826 | M15: -28524
A16: Ταμειακά διαθέσιμα και ισοδύναμα | B16: 9737271 | C16: 10749735 | D16: 7221288 | E16: 21735612 | F16: 16995156 | H16: Χρηματοοικονομικό αποτέλεσμα (καθαρό) | I16: -185576 | J16: -136283 | K16: -194985 | L16: 23373 | M16: 316353
A17: Σύνολο κυκλοφορούντος ενεργητικού | B17: 49742620 | C17: 47899250 | D17: 53321210 | E17: 77526884 | F17: 74689969 | H17: Κέρδη προ φόρων | I17: 18422010 | J17: 16529604 | K17: 3832647 | L17: 40301025 | M17: 37566134
A18: Σύνολο ενεργητικού | B18: 115407570 | C18: 119974280 | D18: 128097844 | E18: 160496937 | F18: 178037686 | H18: Φόρος εισοδήματος | I18: -2559398 | J18: -3319914 | K18: -657646 | L18: -8031805 | M18: -3019115
A19: ΙΔΙΑ ΚΕΦΑΛΑΙΑ & ΥΠΟΧΡΕΩΣΕΙΣ | H19: Κέρδη μετά από φόρους (A) | I19: 15862612 | J19: 13209690 | K19: 3175001 | L19: 32269220 | M19: 34547018
A20: Ίδια κεφάλαια
A21: Μετοχικό κεφάλαιο | B21: 12564752 | C21: 12564752 | D21: 12564752 | E21: 12564752 | F21: 12564752 | H21: Δείκτες
A22: Αποθεματικά | B22: 22437778 | C22: 24551367 | D22: 24686060 | E22: 35687373 | F22: 38802072 | H22: Δείκτες Κερδοφορίας
A23: Αποθεματικό ιδίων μετοχών | C23: -60897 | D23: -541306 | E23: -455051 | F23: -898702 | H23: ROE | I23: =I19/B25 -> 0.2090404 | J23: =J19/C25 -> 0.15947768 | K23: =K19/D25 -> 0.040239743 | L23: =L19/E25 -> 0.30820855 | M23: =M19/F25 -> 0.27105484
A24: Κέρδη εις νέον | B24: 41014778 | C24: 45775743 | D24: 42192614 | E24: 56902229 | F24: 76985856 | H24: ROA | I24: =I19/B18 -> 0.13744863 | J24: =J19/C18 -> 0.11010435 | K24: =K19/D18 -> 0.024785749 | L24: =L19/E18 -> 0.20105817 | M24: =M19/F18 -> 0.19404329
A25: Σύνολο ιδίων κεφαλαίων | B25: 75882997 | C25: 82830965 | D25: 78902120 | E25: 104699303 | F25: 127453978 | H25: ROCE | I25: =I10/(B18-B39) -> 0.19561145 | J25: =J10/(C18-C39) -> 0.1671485 | K25: =K10/(D18-D39) -> 0.041904673 | L25: =L10/(E18-E39) -> 0.3191412 | M25: =M10/(F18-F39) -> 0.25963097
A26: Υποχρεώσεις | H26: Δείκτες Μόχλευσης
A27: Μακροπρόθεσμες υποχρεώσεις | H27: Net Dept/Ebidta | I27: =(B28+B29+B35+B36-B16)/I12 -> 0.071428515 | J27: =(C28+C29+C35+C36-C16)/J12 -> -0.066294852 | K27: =(D28+D29+D35+D36-D16)/K12 -> 0.86560082 | L27: =(E28+E29+E35+E36-E16)/L12 -> -0.20244707 | M27: =(F28+F29+F35+F36-F16)/M12 -> -0.28386062
A28: Μακροπρόθεσμες δανειακές υποχρεώσεις | B28: 8680000 | C28: 6430000 | D28: 6750000 | E28: 10230000 | F28: 4299924 | H28: Dept/Equity | I28: =(B29+B28+B35+B36)/B25 -> 0.14971786 | J28: =(C29+C28+C35+C36)/C25 -> 0.11267703 | K28: =(D29+D28+D35+D36)/D25 -> 0.19317432 | L28: =(E29+E28+E35+E36)/E25 -> 0.11960609 | M28: =(F29+F28+F35+F36)/F25 -> 0.037620144
A29: Μακροπρόθεσμες υποχρεώσεις μισθώσεων | B29: 243413 | C29: 428068 | D29: 355857 | E29: 376253 | F29: 280218 | H29: Τόκοι / Κέρδη | I29: =-(I14+I15)/I19 -> 0.019588577 | J29: =-(J14+J15)/J19 -> 0.023311221 | K29: =-(K14+K15)/K19 -> 0.091302018 | L29: =-(L14+L15)/L19 -> 0.013330629 | M29: =-(M14+M15)/M19 -> 0.008551013
A30: Υποχρεώσεις παροχών συνταξιοδότησης | B30: 604307 | C30: 285270 | D30: 304149 | E30: 376429 | F30: 476541 | H30: Δείκτες Ρευστότητας
A31: Αναβαλλόμενες φορολογικές υποχρεώσεις | B31: 3382217 | C31: 3805295 | D31: 4277489 | E31: 5384001 | F31: 6201601 | H31: Working Capital | I31: =B17-B39 -> 29460287 | J31: =C17-C39 -> 27632038 | K31: =D17-D39 -> 21337516 | L31: =E17-E39 -> 43236314 | M31: =F17-F39 -> 40124308
A32: Επιχορηγήσεις | B32: 6322303 | C32: 5927470 | D32: 5524536 | E32: 5140381 | F32: 4759763 | H32: Current Ratio | I32: =B17/B39 -> 2.4525098 | J32: =C17/C39 -> 2.3633862 | K32: =D17/D39 -> 1.6671373 | L32: =E17/E39 -> 2.2608806 | M32: =F17/F39 -> 2.1608141
A33: Σύνολο μακροπρόθεσμων υποχρεώσεων | B33: 19242240 | C33: 16876103 | D33: 17212031 | E33: 21507064 | F33: 16018047 | H33: Quick Ratio | I33: =(B17-B11)/B39 -> 1.7610611 | J33: =(C17-C11)/C39 -> 1.777622 | K33: =(D17-D11)/D39 -> 1.1890803 | L33: =(E17-E11)/E39 -> 1.7567011 | M33: =(F17-F11)/F39 -> 1.4437961
A34: Βραχυπρόθεσμες υποχρεώσεις | H34: Δείκτες Δραστηριότητας
A35: Βραχυπρόθεσμες δανειακές υποχρεώσεις | B35: 2249837 | C35: 2250628 | D35: 7945948 | E35: 1674236 | F35: 0 | H35: Μερες Αποθέματα
A36: Βραχυπρόθεσμες υποχρεώσεις μισθώσεων | B36: 187790 | C36: 224451 | D36: 190058 | E36: 242185 | F36: 214695 | H36: Μέρες Απαιτήσεων
A37: Προμηθευτές και λοιπές υποχρεώσεις | B37: 17844706 | C37: 17345408 | D37: 23847688 | E37: 25743242 | F37: 33699877 | H37: Δείκτες Αποτίμησης
A38: Υποχρεώσεις από φόρο εισοδήματος | B38: 0 | C38: 446725 | D38: 0 | E38: 6630907 | F38: 651089 | H38: Price @ 31/12 | I38: ='Kri-Kri Milk Stock Price Histor'!B53 -> 6.54 | J38: ='Kri-Kri Milk Stock Price Histor'!B105 -> 8.5 | K38: ='Kri-Kri Milk Stock Price Histor'!B157 -> 6.2 | L38: ='Kri-Kri Milk Stock Price Histor'!B210 -> 9.8 | M38: ='Kri-Kri Milk Stock Price Histor'!B262 -> 15.55
A39: Σύνολο βραχυπρόθεσμων υποχρεώσεων | B39: 20282333 | C39: 20267212 | D39: 31983694 | E39: 34290570 | F39: 34565661 | H39: Απόδοση από προηγ. χρόνο | I39: - | J39: =(J38-I38)/I38 -> 0.29969419 | K39: =(K38-J38)/J38 -> -0.27058824 | L39: =(L38-K38)/K38 -> 0.58064516 | M39: =(M38-L38)/L38 -> 0.58673469
A40: Σύνολο υποχρεώσεων | B40: 39524573 | C40: 37143315 | D40: 49195725 | E40: 55797634 | F40: 50583708 | H40: Αριθμός Μετοχών | I40: 33063986 | J40: 32956971 | K40: 32947090 | L40: 32992055 | M40: 32996552
...

Sheet ATG companies
A1: Name | B1: Market Cap | C1: P/E Ratio | G1: 2020 | H1: 2021 | I1: 2022 | J1: 2023 | K1: 2024 | M1: TOTAL MARKET CAP
A2: Coca Cola HBC AG | B2: 15980000000 | C2: 17.56 | F2: Coca Cola
A3: Eurobank Ergasias | B3: 12770000000 | C3: 9.5 | F3: Price @31/12 | G3: 26.42 | H3: 30.26 | I3: 22.6 | J3: 26.57 | K3: 33.3
A4: Piraeus Bank | B4: 8700000000 | C4: 8.75 | F4: Market Cap | G4: =G3*364300000 -> 9624806000 | H4: =H3*364300000 -> 11023718000 | I4: =I3*364300000 -> 8.23318e+09 | J4: =J3*364300000 -> 9679451000 | K4: =K3*364300000 -> 1.213119e+10
A5: Alpha Bank | B5: 8330000000 | C5: 10.4 | F5: Net Income | G5: =1000000*414.9 -> 414900000 | H5: =1000000*547.2 -> 547200000 | I5: =1000000*415.4 -> 415400000 | J5: =1000000*636.5 -> 636500000 | K5: =1000000*820.6 -> 820600000
A6: Public Power | B6: 6270000000 | C6: 16.8 | F6: EV | G6: =G4+G8-G9 -> 11134506000 | H6: =H4+H8-H9 -> 12943318000 | I6: =I4+I8-I9 -> 10765680000 | J6: =J4+J8-J9 -> 11629651000 | K6: =K4+K8-K9 -> 1.434599e+10
A7: Jumbo | B7: 3780000000 | C7: 12.06 | F7: Equity | G7: 2633300000 | H7: 3117100000 | I7: 3385600000 | J7: 3186700000 | K7: 3303000000
A8: Bank of Cyprus Holdings | B8: 3480000000 | C8: 7.55 | F8: Debt | G8: 2725500000 | H8: =2702.4*1000000 -> 2702400000 | I8: =1000000*3252.4 -> 3252400000 | J8: =1000000*3210.8 -> 3210800000 | K8: =1000000*3762.9 -> 3762900000
A9: Athens International Airport | B9: 3360000000 | C9: 13.93 | F9: Cash & Equiv. | G9: =1000000*1215.8 -> 1215800000 | H9: =1000000*782.8 -> 782800000 | I9: =1000000*719.9 -> 719900000 | J9: =1000000*1260.6 -> 1260600000 | K9: =1000000*1548.1 -> 1548100000
A10: Cenergy Hold | B10: 3180000000 | C10: 16.96 | F10: EBIDTA | G10: =1000000*967.3 -> 967300000 | H10: =1000000*1078.4 -> 1078400000 | I10: =1000000*1224.9 -> 1224900000 | J10: =1000000*1286.6 -> 1286600000 | K10: =1000000*1490.8 -> 1490800000
A11: HELLENiQ ENERGY Holdings | B11: 2600000000 | C11: 15.26 | F11: ROE | G11: =G5/G7 -> 0.15755896 | H11: =H5/H7 -> 0.17554778 | I11: =I5/I7 -> 0.12269612 | J11: =J5/J7 -> 0.1997364 | K11: =K5/K7 -> 0.24844081
A12: Aktor Symmetochon Technikon kai Energoiakon Ergon | B12: 1890000000 | C12: 133.67 | F12: P/E | G12: =G4/G5 -> 23.197893 | H12: =H4/H5 -> 20.145683 | I12: =I4/I5 -> 19.819884 | J12: =J4/J5 -> 15.207307 | K12: =K4/K5 -> 14.783317
A13: Elvalhalcor Hellenic | B13: 1470000000 | C13: 11.7 | F13: Ev/Ebidta | G13: =G6/G10 -> 11.510913 | H13: =H6/H10 -> 12.002335 | I13: =I6/I10 -> 8.7890277 | J13: =J6/J10 -> 9.0390572 | K13: =K6/K10 -> 9.6230145
A14: Aegean Airlines | B14: 1290000000 | C14: 8.84 | F14: Divident Yield | G14: 0.0278 | H14: 0.0207 | I14: 0.0329 | J14: 0.0517 | K14: 0.0291
A15: Athens Water | B15: 823250000 | C15: -832.26 | F15: Eurobank
A16: Holding Company ADMIE | B16: 697670000 | C16: 9.9 | F16: Price @31/12 | G16: 0.5786 | H16: 0.8914 | I16: 1.055 | J16: 1.61 | K16: 2.284
A17: Autohellas | B17: 568590000 | C17: 7 | F17: Market Cap | G17: =G16*3698275862 -> 2.1398224e+09 | H17: =H16*3698275862 -> 3.2966431e+09 | I17: =I16*3698275862 -> 3.901681e+09 | J17: =J16*3698275862 -> 5.9542241e+09 | K17: =K16*3698275862 -> 8.4468621e+09
A18: Ellaktor | B18: 461780000 | C18: -15.85 | F18: Net Income | G18: =1000000*-1215 -> -1215000000 | H18: =1000000*328 -> 328000000 | I18: =1000000*1347 -> 1347000000 | J18: =1000000*1140 -> 1140000000 | K18: =1000000*1448 -> 1448000000
A19: Avax | B19: 416580000 | C19: 7.13 | F19: EV | G19: =G17+G21-G22 -> 1.2284822e+10 | H19: =H17+H21-H22 -> 1.7678643e+10 | I19: =I17+I21-I22 -> 1.6938681e+10 | J19: =J17+J21-J22 -> 1.6083224e+10 | K19: =K17+K21-K22 -> 1.6261862e+10
A20: Alter Ego Media | B20: 367330000 | C20: 22.47 | F20: Equity | G20: =1000000*5262 -> 5262000000 | H20: =1000000*5635 -> 5635000000 | I20: =1000000*6732 -> 6732000000 | J20: =1000000*7899 -> 7899000000 | K20: =1000000*8899 -> 8899000000
A21: Hellenic Exchanges | B21: 362720000 | C21: 11.77 | F21: Debt | G21: =(10980+37+184)*1000000 -> 11201000000 | H21: =(15117+36+212)*1000000 -> 15365000000 | I21: =(13770+37+168)*1000000 -> 13975000000 | J21: =1000000*(11439+75+115) -> 11629000000 | K21: =1000000*(9634+40+150) -> 9824000000
A22: Evropi Holdings | B22: 280970000 | C22: 10.15 | F22: Cash & Equiv. | G22: =1000000*1056 -> 1056000000 | H22: =1000000*983 -> 983000000 | I22: =1000000*938 -> 938000000 | J22: =1000000*1500 -> 1500000000 | K22: =1000000*2009 -> 2009000000
A23: Austriacard Holdings | B23: 214700000 | C23: 18.9 | F23: EBIDTA
A24: Fourlis Hld | B24: 210130000 | C24: 12.1 | F24: ROE | G24: =G18/G20 -> -0.2309008 | H24: =H18/H20 -> 0.058207631 | I24: =I18/I20 -> 0.20008913 | J24: =J18/J20 -> 0.14432207 | K24: =K18/K20 -> 0.16271491
A25: Dimand Societe Anonyme for Real Estate Constructio | B25: 200280000 | C25: 5.27 | F25: P/E | G25: =G17/G18 -> -1.7611707 | H25: =H17/H18 -> 10.050741 | I25: =I17/I18 -> 2.8965709 | J25: =J17/J18 -> 5.2230036 | K25: =K17/K18 -> 5.8334683
A26: BLE Kedros RE Investment | B26: 171220000 | C26: 17.54 | F26: Ev/Ebidta
A27: Athens Medical | B27: 167830000 | C27: -36.08 | F27: Divident Yield | G27: =0.02/G16 -> 0.034566194 | H27: 0 | I27: 0 | J27: 0 | K27: =0.09/K16 -> 0.039404553
A28: Alumil | B28: 162070000 | C28: 9.59 | F28: Jumbo
A29: BriQ Properties | B29: 137370000 | C29: 4.7 | F29: Price @31/12 | G29: 14.2 | H29: =12.6 -> 12.6 | I29: =15.98 -> 15.98 | J29: =25.12 -> 25.12 | K29: =25.56 -> 25.56
A30: Ekter | B30: 97440000 | C30: 10.17 | F30: Market Cap | G30: =1000000000*1.933 -> 1933000000 | H30: =1000000000*1.714 -> 1714000000 | I30: =1000000000*2.174 -> 2174000000 | J30: =1000000000*3.418 -> 3418000000 | K30: =1000000000*3.454 -> 3454000000
A31: AS Company | B31: 52620000 | C31: 12.68 | F31: Net Income | G31: =1000000*138.67 -> 138670000 | H31: =1000000*216.59 -> 216590000 | I31: =1000000*248.6 -> 248600000 | J31: =1000000*303 -> 303000000 | K31: =1000000*320.1 -> 320100000
B32: =SUM(B1:B31) -> 78492550000 | C32: =SUMPRODUCT(B2:B31,C2:C31)/B32 -> 6.4814678 | D32: =1/C32 -> 0.15428604 | F32: EV | G32: =G30+G34-G35 -> 1858610000 | H32: =H30+H34-H35 -> 1398170000 | I32: =I30+I34-I35 -> 1860750000 | J32: =J30+J34-J35 -> 3058010000 | K32: =K30+K34-K35 -> 3084360000
F33: Equity | G33: =1000000*1219.49 -> 1219490000 | H33: =1000000*1328.33 -> 1328330000 | I33: =1000000*1421.86 -> 1421860000 | J33: =1000000*1327.57 -> 1327570000 | K33: =1000000*1408.14 -> 1408140000
F34: Debt | G34: 305830000 | H34: 288990000 | I34: 280460000 | J34: 74010000 | K34: 75180000
F35: Cash & Equiv. | G35: =1000000*380.22 -> 380220000 | H35: =1000000*604.82 -> 604820000 | I35: =1000000*593.71 -> 593710000 | J35: =1000000*434 -> 434000000 | K35: =1000000*444.82 -> 444820000
F36: EBIDTA | G36: =1000000*197.6 -> 197600000 | H36: =1000000*291.4 -> 291400000 | I36: =1000000*327.8 -> 327800000 | J36: =1000000*389.6 -> 389600000 | K36: =1000000*415.6 -> 415600000
F37: ROE | G37: =G31/G33 -> 0.11371147 | H37: =H31/H33 -> 0.16305436 | I37: =I31/I33 -> 0.1748414 | J37: =J31/J33 -> 0.22823655 | K37: =K31/K33 -> 0.22732115
F38: P/E | G38: =G30/G31 -> 13.939569 | H38: =H30/H31 -> 7.9135694 | I38: =I30/I31 -> 8.7449718 | J38: =J30/J31 -> 11.280528 | K38: =K30/K31 -> 10.790378
F39: Ev/Ebidta | G39: =G32/G36 -> 9.4059211 | H39: =H32/H36 -> 4.7981126 | I39: =I32/I36 -> 5.6764796 | J39: =J32/J36 -> 7.8491016 | K39: =K32/K36 -> 7.4214629
F40: Divident Yield | G40: =(0.38+0.24+0.06+0.22)/G29 -> 0.063380282 | H40: =(0.3+0.47)/H29 -> 0.061111111 | I40: =(0.39*3)/I29 -> 0.073216521 | J40: =(1.16+0.32+1.47)/J29 -> 0.11743631 | K40: =(1.6)/K29 -> 0.062597809
...

Sheet Peer
B1: 2020 | C1: 2021 | D1: 2022 | E1: 2023 | F1: 2024
A2: Coca Cola
A3: Price @31/12 | B3: 26.42 | C3: 30.26 | D3: 22.6 | E3: 26.57 | F3: 33.3 | G3: Αποδοση | H3: =(F3-C3)/C3 -> 0.10046266
A4: Market Cap | B4: =B3*364300000 -> 9624806000 | C4: =C3*364300000 -> 11023718000 | D4: =D3*364300000 -> 8.23318e+09 | E4: =E3*364300000 -> 9679451000 | F4: =F3*364300000 -> 1.213119e+10
A5: Net Income | B5: =1000000*414.9 -> 414900000 | C5: =1000000*547.2 -> 547200000 | D5: =1000000*415.4 -> 415400000 | E5: =1000000*636.5 -> 636500000 | F5: =1000000*820.6 -> 820600000
A6: EV | B6: =B4+B8-B9 -> 11134506000 | C6: =C4+C8-C9 -> 12943318000 | D6: =D4+D8-D9 -> 10765680000 | E6: =E4+E8-E9 -> 11629651000 | F6: =F4+F8-F9 -> 1.434599e+10
A7: Equity | B7: 2633300000 | C7: 3117100000 | D7: 3385600000 | E7: 3186700000 | F7: 3303000000
A8: Debt | B8: 2725500000 | C8: =2702.4*1000000 -> 2702400000 | D8: =1000000*3252.4 -> 3252400000 | E8: =1000000*3210.8 -> 3210800000 | F8: =1000000*3762.9 -> 3762900000
A9: Cash & Equiv. | B9: =1000000*1215.8 -> 1215800000 | C9: =1000000*782.8 -> 782800000 | D9: =1000000*719.9 -> 719900000 | E9: =1000000*1260.6 -> 1260600000 | F9: =1000000*1548.1 -> 1548100000
A10: EBIDTA | B10: =1000000*967.3 -> 967300000 | C10: =1000000*1078.4 -> 1078400000 | D10: =1000000*1224.9 -> 1224900000 | E10: =1000000*1286.6 -> 1286600000 | F10: =1000000*1490.8 -> 1490800000
A11: ROE | B11: =B5/B7 -> 0.15755896 | C11: =C5/C7 -> 0.17554778 | D11: =D5/D7 -> 0.12269612 | E11: =E5/E7 -> 0.1997364 | F11: =F5/F7 -> 0.24844081
A12: P/E | B12: =B4/B5 -> 23.197893 | C12: =C4/C5 -> 20.145683 | D12: =D4/D5 -> 19.819884 | E12: =E4/E5 -> 15.207307 | F12: =F4/F5 -> 14.783317
A13: Ev/Ebidta | B13: =B6/B10 -> 11.510913 | C13: =C6/C10 -> 12.002335 | D13: =D6/D10 -> 8.7890277 | E13: =E6/E10 -> 9.0390572 | F13: =F6/F10 -> 9.6230145
A14: Divident Yield | B14: 0.0278 | C14: 0.0207 | D14: 0.0329 | E14: 0.0517 | F14: 0.0291
A15: Nestle
A16: Price @31/12 | B16: 104.26 | C16: 127.44 | D16: 107.14 | E16: 97.51 | F16: 74.88 | H16: =(F16-B16)/B16 -> -0.28179551
A17: Market Cap | B17: =290.4*1000000000 -> 290400000000 | C17: =350.5*1000000000 -> 350500000000 | D17: =295.7*1000000000 -> 295700000000 | E17: =252.4*1000000000 -> 252400000000 | F17: =192.5*1000000000 -> 192500000000
A18: Net Income | B18: =12.232*1000000000 -> 12232000000 | C18: =16.905*1000000000 -> 1.6905e+10 | D18: =9.27*1000000000 -> 9270000000 | E18: =11.209*1000000000 -> 11209000000 | F18: =10.884*1000000000 -> 10884000000
A19: EV | B19: =B17+B21-B22 -> 320210000000 | C19: =C17+C21-C22 -> 386102000000 | D19: =D17+D21-D22 -> 340679000000 | E19: =E17+E21-E22 -> 300612000000 | F19: =F17+F21-F22 -> 245904000000
A20: Equity | B20: =1000000*46514 -> 46514000000 | C20: =1000000*53727 -> 53727000000 | D20: =1000000*42792 -> 42792000000 | E20: =1000000*36387 -> 36387000000 | F20: =1000000*36693 -> 36693000000
A21: Debt | B21: =1000000*35045 -> 35045000000 | C21: =1000000*42590 -> 42590000000 | D21: =1000000*50490 -> 50490000000 | E21: =1000000*53028 -> 53028000000 | F21: =1000000*58960 -> 58960000000
A22: Cash & Equiv. | B22: =1000000*5235 -> 5235000000 | C22: =1000000*6988 -> 6988000000 | D22: =1000000*5511 -> 5511000000 | E22: =1000000*4816 -> 4816000000 | F22: =1000000*5556 -> 5556000000
A23: EBIDTA | B23: =16.826*1000000000 -> 16826000000 | C23: =17.145*1000000000 -> 17145000000 | D23: =18.238*1000000000 -> 18238000000 | E23: =18.156*1000000000 -> 18156000000 | F23: =18.177*1000000000 -> 18177000000
A24: ROE | B24: =B18/B20 -> 0.26297459 | C24: =C18/C20 -> 0.31464627 | D24: =D18/D20 -> 0.21662928 | E24: =E18/E20 -> 0.30804958 | F24: =F18/F20 -> 0.29662333
A25: P/E | B25: =B17/B18 -> 23.741007 | C25: =C17/C18 -> 20.733511 | D25: =D17/D18 -> 31.898598 | E25: =E17/E18 -> 22.51762 | F25: =F17/F18 -> 17.686512
A26: Ev/Ebidta | B26: =B19/B23 -> 19.030667 | C26: =C19/C23 -> 22.519802 | D26: =D19/D23 -> 18.679625 | E26: =E19/E23 -> 16.557171 | F26: =F19/F23 -> 13.528305
A27: Divident Yield | B27: =2.7/B16 -> 0.025896796 | C27: =2.75/C16 -> 0.021578782 | D27: =2.8/D16 -> 0.02613403 | E27: =2.95/E16 -> 0.030253307 | F27: =3/F16 -> 0.040064103
A28: KRI KRI
A29: ROE | B29: 0.2090404 | C29: 0.15947768 | D29: 0.040239743 | E29: 0.30820855 | F29: 0.27105484
A30: P/E | B30: 13.631958 | C30: 21.206724 | D30: 64.337604 | E30: 10.019521 | F30: 14.852118
A31: EV/EBIDTA | B31: 9.5836145 | C31: 13.043698 | D31: 22.911149 | E31: 6.9023026 | F31: 11.654176
A32: Divident Yield | B32: 0.025805075 | C32: 0.024903638 | D32: 0.032350931 | E32: 0.020436884 | F32: 0.022549839
